2025-01-29 04:34:30 - WARNING - This is a warning message with local timezone.
2025-01-29 04:34:30 - WARNING - PyNaCl is not installed, voice will NOT be supported
2025-01-29 04:34:30 - INFO - logging in using static token
2025-01-29 04:34:33 - INFO - Shard ID None has connected to Gateway (Session ID: 270d1b12e632f01baf11541afd31b0ef).
2025-01-29 04:34:37 - ERROR - File 'c:\Users\huyth\OneDrive\Documents\Code\My projects\husci\public\data\users.json' không h\u1ee3p l\u1ec7. Tr\u1ea3 v\u1ec1 danh sách r\u1ed7ng
2025-01-29 04:34:37 - ERROR - File 'c:\Users\huyth\OneDrive\Documents\Code\My projects\husci\public\data\guilds_info.json' không h\u1ee3p l\u1ec7. Tr\u1ea3 v\u1ec1 danh sách r\u1ed7ng
2025-01-29 04:34:37 - ERROR - File 'c:\Users\huyth\OneDrive\Documents\Code\My projects\husci\public\data\unique_member_ids.json' không h\u1ee3p l\u1ec7. Tr\u1ea3 v\u1ec1 danh sách r\u1ed7ng
2025-01-29 04:34:37 - ERROR - Unhandled exception in internal background task 'one_minute'.
Traceback (most recent call last):
  File "C:\Users\huyth\AppData\Local\Programs\Python\Python313\Lib\site-packages\discord\ext\tasks\__init__.py", line 241, in _loop
    await self.coro(*args, **kwargs)
  File "c:\Users\huyth\OneDrive\Documents\Code\My projects\husci\public\app.py", line 72, in one_minute
    await loops.handle_auto_notifications(previous_notifications)
  File "c:\Users\huyth\OneDrive\Documents\Code\My projects\husci\public\modules\loops.py", line 22, in handle_auto_notifications
    data = json.load(file)
  File "C:\Users\huyth\AppData\Local\Programs\Python\Python313\Lib\json\__init__.py", line 293, in load
    return loads(fp.read(),
        cls=cls, object_hook=object_hook,
        parse_float=parse_float, parse_int=parse_int,
        parse_constant=parse_constant, object_pairs_hook=object_pairs_hook, **kw)
  File "C:\Users\huyth\AppData\Local\Programs\Python\Python313\Lib\json\__init__.py", line 346, in loads
    return _default_decoder.decode(s)
           ~~~~~~~~~~~~~~~~~~~~~~~^^^
  File "C:\Users\huyth\AppData\Local\Programs\Python\Python313\Lib\json\decoder.py", line 345, in decode
    obj, end = self.raw_decode(s, idx=_w(s, 0).end())
               ~~~~~~~~~~~~~~~^^^^^^^^^^^^^^^^^^^^^^^
  File "C:\Users\huyth\AppData\Local\Programs\Python\Python313\Lib\json\decoder.py", line 363, in raw_decode
    raise JSONDecodeError("Expecting value", s, err.value) from None
json.decoder.JSONDecodeError: Expecting value: line 1 column 1 (char 0)
2025-01-29 04:34:42 - ERROR - File 'c:\Users\huyth\OneDrive\Documents\Code\My projects\husci\public\data\users.json' không h\u1ee3p l\u1ec7. Tr\u1ea3 v\u1ec1 danh sách r\u1ed7ng
2025-01-29 04:34:47 - ERROR - File 'c:\Users\huyth\OneDrive\Documents\Code\My projects\husci\public\data\users.json' không h\u1ee3p l\u1ec7. Tr\u1ea3 v\u1ec1 danh sách r\u1ed7ng
2025-01-29 04:34:52 - ERROR - File 'c:\Users\huyth\OneDrive\Documents\Code\My projects\husci\public\data\users.json' không h\u1ee3p l\u1ec7. Tr\u1ea3 v\u1ec1 danh sách r\u1ed7ng
2025-01-29 04:34:57 - ERROR - File 'c:\Users\huyth\OneDrive\Documents\Code\My projects\husci\public\data\users.json' không h\u1ee3p l\u1ec7. Tr\u1ea3 v\u1ec1 danh sách r\u1ed7ng
2025-01-29 04:35:06 - WARNING - This is a warning message with local timezone.
2025-01-29 04:35:06 - WARNING - PyNaCl is not installed, voice will NOT be supported
2025-01-29 04:35:06 - INFO - logging in using static token
2025-01-29 04:35:08 - INFO - Shard ID None has connected to Gateway (Session ID: 64c989e9090448aaf2d790dfa027f665).
2025-01-29 04:35:11 - ERROR - File 'c:\Users\huyth\OneDrive\Documents\Code\My projects\husci\public\data\users.json' không h\u1ee3p l\u1ec7. Tr\u1ea3 v\u1ec1 danh sách r\u1ed7ng
2025-01-29 04:35:11 - ERROR - Unhandled exception in internal background task 'one_minute'.
Traceback (most recent call last):
  File "C:\Users\huyth\AppData\Local\Programs\Python\Python313\Lib\site-packages\discord\ext\tasks\__init__.py", line 241, in _loop
    await self.coro(*args, **kwargs)
  File "c:\Users\huyth\OneDrive\Documents\Code\My projects\husci\public\app.py", line 72, in one_minute
    await loops.handle_auto_notifications(previous_notifications)
  File "c:\Users\huyth\OneDrive\Documents\Code\My projects\husci\public\modules\loops.py", line 22, in handle_auto_notifications
    data = json.load(file)
  File "C:\Users\huyth\AppData\Local\Programs\Python\Python313\Lib\json\__init__.py", line 293, in load
    return loads(fp.read(),
        cls=cls, object_hook=object_hook,
        parse_float=parse_float, parse_int=parse_int,
        parse_constant=parse_constant, object_pairs_hook=object_pairs_hook, **kw)
  File "C:\Users\huyth\AppData\Local\Programs\Python\Python313\Lib\json\__init__.py", line 346, in loads
    return _default_decoder.decode(s)
           ~~~~~~~~~~~~~~~~~~~~~~~^^^
  File "C:\Users\huyth\AppData\Local\Programs\Python\Python313\Lib\json\decoder.py", line 345, in decode
    obj, end = self.raw_decode(s, idx=_w(s, 0).end())
               ~~~~~~~~~~~~~~~^^^^^^^^^^^^^^^^^^^^^^^
  File "C:\Users\huyth\AppData\Local\Programs\Python\Python313\Lib\json\decoder.py", line 363, in raw_decode
    raise JSONDecodeError("Expecting value", s, err.value) from None
json.decoder.JSONDecodeError: Expecting value: line 1 column 1 (char 0)
2025-01-29 04:35:16 - ERROR - File 'c:\Users\huyth\OneDrive\Documents\Code\My projects\husci\public\data\users.json' không h\u1ee3p l\u1ec7. Tr\u1ea3 v\u1ec1 danh sách r\u1ed7ng
2025-01-29 04:35:21 - ERROR - File 'c:\Users\huyth\OneDrive\Documents\Code\My projects\husci\public\data\users.json' không h\u1ee3p l\u1ec7. Tr\u1ea3 v\u1ec1 danh sách r\u1ed7ng
2025-01-29 04:35:26 - ERROR - File 'c:\Users\huyth\OneDrive\Documents\Code\My projects\husci\public\data\users.json' không h\u1ee3p l\u1ec7. Tr\u1ea3 v\u1ec1 danh sách r\u1ed7ng
2025-01-29 04:38:58 - WARNING - This is a warning message with local timezone.
2025-01-29 04:38:58 - WARNING - PyNaCl is not installed, voice will NOT be supported
2025-01-29 04:38:58 - INFO - logging in using static token
2025-01-29 04:39:00 - INFO - Shard ID None has connected to Gateway (Session ID: 654b18995b5c970a78bf0c5cc6d74336).
2025-01-29 04:39:03 - ERROR - File 'c:\Users\huyth\OneDrive\Documents\Code\My projects\husci\public\data\users.json' không h\u1ee3p l\u1ec7. Tr\u1ea3 v\u1ec1 danh sách r\u1ed7ng
2025-01-29 04:39:03 - ERROR - Unhandled exception in internal background task 'one_minute'.
Traceback (most recent call last):
  File "C:\Users\huyth\AppData\Local\Programs\Python\Python313\Lib\site-packages\discord\ext\tasks\__init__.py", line 241, in _loop
    await self.coro(*args, **kwargs)
  File "c:\Users\huyth\OneDrive\Documents\Code\My projects\husci\public\app.py", line 72, in one_minute
    await loops.handle_auto_notifications(previous_notifications)
  File "c:\Users\huyth\OneDrive\Documents\Code\My projects\husci\public\modules\loops.py", line 22, in handle_auto_notifications
    data = json.load(file)
  File "C:\Users\huyth\AppData\Local\Programs\Python\Python313\Lib\json\__init__.py", line 293, in load
    return loads(fp.read(),
        cls=cls, object_hook=object_hook,
        parse_float=parse_float, parse_int=parse_int,
        parse_constant=parse_constant, object_pairs_hook=object_pairs_hook, **kw)
  File "C:\Users\huyth\AppData\Local\Programs\Python\Python313\Lib\json\__init__.py", line 346, in loads
    return _default_decoder.decode(s)
           ~~~~~~~~~~~~~~~~~~~~~~~^^^
  File "C:\Users\huyth\AppData\Local\Programs\Python\Python313\Lib\json\decoder.py", line 345, in decode
    obj, end = self.raw_decode(s, idx=_w(s, 0).end())
               ~~~~~~~~~~~~~~~^^^^^^^^^^^^^^^^^^^^^^^
  File "C:\Users\huyth\AppData\Local\Programs\Python\Python313\Lib\json\decoder.py", line 363, in raw_decode
    raise JSONDecodeError("Expecting value", s, err.value) from None
json.decoder.JSONDecodeError: Expecting value: line 1 column 1 (char 0)
2025-01-29 12:27:10 - WARNING - This is a warning message with local timezone.
2025-01-29 12:27:11 - WARNING - PyNaCl is not installed, voice will NOT be supported
2025-01-29 12:27:11 - INFO - logging in using static token
2025-01-29 12:27:13 - INFO - Shard ID None has connected to Gateway (Session ID: 000b87e89fcf153c44cc17b73d044946).
2025-01-29 12:27:16 - ERROR - File 'c:\Users\huyth\OneDrive\Documents\Code\My projects\husci\public\data\users.json' không h\u1ee3p l\u1ec7. Tr\u1ea3 v\u1ec1 danh sách r\u1ed7ng
2025-01-29 12:27:16 - ERROR - Unhandled exception in internal background task 'one_minute'.
Traceback (most recent call last):
  File "C:\Users\huyth\AppData\Local\Programs\Python\Python313\Lib\site-packages\discord\ext\tasks\__init__.py", line 241, in _loop
    await self.coro(*args, **kwargs)
  File "c:\Users\huyth\OneDrive\Documents\Code\My projects\husci\public\app.py", line 72, in one_minute
    await loops.handle_auto_notifications(previous_notifications)
  File "c:\Users\huyth\OneDrive\Documents\Code\My projects\husci\public\modules\loops.py", line 22, in handle_auto_notifications
    data = json.load(file)
  File "C:\Users\huyth\AppData\Local\Programs\Python\Python313\Lib\json\__init__.py", line 293, in load
    return loads(fp.read(),
        cls=cls, object_hook=object_hook,
        parse_float=parse_float, parse_int=parse_int,
        parse_constant=parse_constant, object_pairs_hook=object_pairs_hook, **kw)
  File "C:\Users\huyth\AppData\Local\Programs\Python\Python313\Lib\json\__init__.py", line 346, in loads
    return _default_decoder.decode(s)
           ~~~~~~~~~~~~~~~~~~~~~~~^^^
  File "C:\Users\huyth\AppData\Local\Programs\Python\Python313\Lib\json\decoder.py", line 345, in decode
    obj, end = self.raw_decode(s, idx=_w(s, 0).end())
               ~~~~~~~~~~~~~~~^^^^^^^^^^^^^^^^^^^^^^^
  File "C:\Users\huyth\AppData\Local\Programs\Python\Python313\Lib\json\decoder.py", line 363, in raw_decode
    raise JSONDecodeError("Expecting value", s, err.value) from None
json.decoder.JSONDecodeError: Expecting value: line 1 column 1 (char 0)
2025-01-29 12:27:21 - ERROR - File 'c:\Users\huyth\OneDrive\Documents\Code\My projects\husci\public\data\users.json' không h\u1ee3p l\u1ec7. Tr\u1ea3 v\u1ec1 danh sách r\u1ed7ng
2025-01-29 12:27:26 - ERROR - File 'c:\Users\huyth\OneDrive\Documents\Code\My projects\husci\public\data\users.json' không h\u1ee3p l\u1ec7. Tr\u1ea3 v\u1ec1 danh sách r\u1ed7ng
2025-01-29 12:27:31 - ERROR - File 'c:\Users\huyth\OneDrive\Documents\Code\My projects\husci\public\data\users.json' không h\u1ee3p l\u1ec7. Tr\u1ea3 v\u1ec1 danh sách r\u1ed7ng
2025-01-29 12:27:36 - WARNING - This is a warning message with local timezone.
2025-01-29 12:27:37 - WARNING - PyNaCl is not installed, voice will NOT be supported
2025-01-29 12:27:37 - INFO - logging in using static token
2025-01-29 12:27:38 - INFO - Shard ID None has connected to Gateway (Session ID: 8f1c5a1dc3d8d4d34d7010772704c134).
2025-01-29 12:28:07 - WARNING - This is a warning message with local timezone.
2025-01-29 12:28:08 - WARNING - PyNaCl is not installed, voice will NOT be supported
2025-01-29 12:28:08 - INFO - logging in using static token
2025-01-29 12:28:09 - INFO - Shard ID None has connected to Gateway (Session ID: f8f99c1fcf7370ab57cc4598bde36030).
2025-01-29 12:28:46 - ERROR - File 'c:\Users\huyth\OneDrive\Documents\Code\My projects\husci\public\data\users.json' không h\u1ee3p l\u1ec7. Tr\u1ea3 v\u1ec1 danh sách r\u1ed7ng
2025-01-29 12:28:46 - ERROR - Unhandled exception in internal background task 'one_minute'.
Traceback (most recent call last):
  File "C:\Users\huyth\AppData\Local\Programs\Python\Python313\Lib\site-packages\discord\ext\tasks\__init__.py", line 241, in _loop
    await self.coro(*args, **kwargs)
  File "c:\Users\huyth\OneDrive\Documents\Code\My projects\husci\public\app.py", line 72, in one_minute
    await loops.handle_auto_notifications(previous_notifications)
  File "c:\Users\huyth\OneDrive\Documents\Code\My projects\husci\public\modules\loops.py", line 22, in handle_auto_notifications
    data = json.load(file)
  File "C:\Users\huyth\AppData\Local\Programs\Python\Python313\Lib\json\__init__.py", line 293, in load
    return loads(fp.read(),
        cls=cls, object_hook=object_hook,
        parse_float=parse_float, parse_int=parse_int,
        parse_constant=parse_constant, object_pairs_hook=object_pairs_hook, **kw)
  File "C:\Users\huyth\AppData\Local\Programs\Python\Python313\Lib\json\__init__.py", line 346, in loads
    return _default_decoder.decode(s)
           ~~~~~~~~~~~~~~~~~~~~~~~^^^
  File "C:\Users\huyth\AppData\Local\Programs\Python\Python313\Lib\json\decoder.py", line 345, in decode
    obj, end = self.raw_decode(s, idx=_w(s, 0).end())
               ~~~~~~~~~~~~~~~^^^^^^^^^^^^^^^^^^^^^^^
  File "C:\Users\huyth\AppData\Local\Programs\Python\Python313\Lib\json\decoder.py", line 363, in raw_decode
    raise JSONDecodeError("Expecting value", s, err.value) from None
json.decoder.JSONDecodeError: Expecting value: line 1 column 1 (char 0)
2025-01-29 12:28:51 - ERROR - File 'c:\Users\huyth\OneDrive\Documents\Code\My projects\husci\public\data\users.json' không h\u1ee3p l\u1ec7. Tr\u1ea3 v\u1ec1 danh sách r\u1ed7ng
2025-01-29 12:28:56 - ERROR - File 'c:\Users\huyth\OneDrive\Documents\Code\My projects\husci\public\data\users.json' không h\u1ee3p l\u1ec7. Tr\u1ea3 v\u1ec1 danh sách r\u1ed7ng
2025-01-29 12:29:01 - ERROR - File 'c:\Users\huyth\OneDrive\Documents\Code\My projects\husci\public\data\users.json' không h\u1ee3p l\u1ec7. Tr\u1ea3 v\u1ec1 danh sách r\u1ed7ng
2025-01-29 12:29:06 - ERROR - File 'c:\Users\huyth\OneDrive\Documents\Code\My projects\husci\public\data\users.json' không h\u1ee3p l\u1ec7. Tr\u1ea3 v\u1ec1 danh sách r\u1ed7ng
2025-01-29 12:29:11 - ERROR - File 'c:\Users\huyth\OneDrive\Documents\Code\My projects\husci\public\data\users.json' không h\u1ee3p l\u1ec7. Tr\u1ea3 v\u1ec1 danh sách r\u1ed7ng
2025-01-29 12:29:16 - ERROR - File 'c:\Users\huyth\OneDrive\Documents\Code\My projects\husci\public\data\users.json' không h\u1ee3p l\u1ec7. Tr\u1ea3 v\u1ec1 danh sách r\u1ed7ng
2025-01-29 12:29:21 - ERROR - File 'c:\Users\huyth\OneDrive\Documents\Code\My projects\husci\public\data\users.json' không h\u1ee3p l\u1ec7. Tr\u1ea3 v\u1ec1 danh sách r\u1ed7ng
2025-01-29 12:29:26 - ERROR - File 'c:\Users\huyth\OneDrive\Documents\Code\My projects\husci\public\data\users.json' không h\u1ee3p l\u1ec7. Tr\u1ea3 v\u1ec1 danh sách r\u1ed7ng
2025-01-29 12:29:31 - ERROR - File 'c:\Users\huyth\OneDrive\Documents\Code\My projects\husci\public\data\users.json' không h\u1ee3p l\u1ec7. Tr\u1ea3 v\u1ec1 danh sách r\u1ed7ng
2025-01-29 12:29:36 - ERROR - File 'c:\Users\huyth\OneDrive\Documents\Code\My projects\husci\public\data\users.json' không h\u1ee3p l\u1ec7. Tr\u1ea3 v\u1ec1 danh sách r\u1ed7ng
2025-01-29 12:29:41 - ERROR - File 'c:\Users\huyth\OneDrive\Documents\Code\My projects\husci\public\data\users.json' không h\u1ee3p l\u1ec7. Tr\u1ea3 v\u1ec1 danh sách r\u1ed7ng
2025-01-29 12:29:46 - ERROR - File 'c:\Users\huyth\OneDrive\Documents\Code\My projects\husci\public\data\users.json' không h\u1ee3p l\u1ec7. Tr\u1ea3 v\u1ec1 danh sách r\u1ed7ng
2025-01-29 12:29:51 - ERROR - File 'c:\Users\huyth\OneDrive\Documents\Code\My projects\husci\public\data\users.json' không h\u1ee3p l\u1ec7. Tr\u1ea3 v\u1ec1 danh sách r\u1ed7ng
2025-01-29 12:30:02 - WARNING - This is a warning message with local timezone.
2025-01-29 12:30:02 - WARNING - PyNaCl is not installed, voice will NOT be supported
2025-01-29 12:30:02 - INFO - logging in using static token
2025-01-29 12:30:04 - INFO - Shard ID None has connected to Gateway (Session ID: 0e0d44233dab82817905ccf966424283).
2025-01-29 12:30:07 - WARNING - Danh sách r\u1ed7ng ho\u1eb7c không có d\u1eef li\u1ec7u.
2025-01-29 12:30:10 - WARNING - Danh sách r\u1ed7ng ho\u1eb7c không có d\u1eef li\u1ec7u.
2025-01-29 12:30:13 - WARNING - Danh sách r\u1ed7ng ho\u1eb7c không có d\u1eef li\u1ec7u.
2025-01-29 12:30:22 - WARNING - This is a warning message with local timezone.
2025-01-29 12:30:22 - WARNING - PyNaCl is not installed, voice will NOT be supported
2025-01-29 12:30:22 - INFO - logging in using static token
2025-01-29 12:30:25 - INFO - Shard ID None has connected to Gateway (Session ID: 05366d4a73bccd1599ec06aeb0feb85b).
2025-01-29 12:33:04 - WARNING - PyNaCl is not installed, voice will NOT be supported
2025-01-29 12:33:04 - INFO - logging in using static token
2025-01-29 12:33:05 - INFO - Shard ID None has connected to Gateway (Session ID: 9745627fd56d9601309bc89b541b5b44).
2025-01-29 12:33:08 - WARNING - Danh sách r\u1ed7ng ho\u1eb7c không có d\u1eef li\u1ec7u.
2025-01-29 12:33:11 - WARNING - Danh sách r\u1ed7ng ho\u1eb7c không có d\u1eef li\u1ec7u.
2025-01-29 12:33:15 - WARNING - Danh sách r\u1ed7ng ho\u1eb7c không có d\u1eef li\u1ec7u.
2025-01-29 12:33:18 - WARNING - Danh sách r\u1ed7ng ho\u1eb7c không có d\u1eef li\u1ec7u.
2025-01-29 12:33:21 - WARNING - Danh sách r\u1ed7ng ho\u1eb7c không có d\u1eef li\u1ec7u.
2025-01-29 12:33:24 - WARNING - Danh sách r\u1ed7ng ho\u1eb7c không có d\u1eef li\u1ec7u.
2025-01-29 12:33:27 - WARNING - Danh sách r\u1ed7ng ho\u1eb7c không có d\u1eef li\u1ec7u.
2025-01-29 12:33:30 - WARNING - Danh sách r\u1ed7ng ho\u1eb7c không có d\u1eef li\u1ec7u.
2025-01-29 12:33:35 - ERROR - File 'c:\Users\huyth\OneDrive\Documents\Code\My projects\husci\public\data\scores\info\23t1080025.json' không h\u1ee3p l\u1ec7. Tr\u1ea3 v\u1ec1 danh sách r\u1ed7ng
2025-01-29 12:33:53 - WARNING - **Ng\u01b0\u1eddi dùng ndn.huy \u0111ã \u0111\u0103ng xu\u1ea5t kh\u1ecfi server Huscier**
2025-01-29 12:34:08 - WARNING - Danh sách r\u1ed7ng ho\u1eb7c không có d\u1eef li\u1ec7u.
2025-01-29 12:34:11 - WARNING - Danh sách r\u1ed7ng ho\u1eb7c không có d\u1eef li\u1ec7u.
2025-01-29 12:34:15 - WARNING - Danh sách r\u1ed7ng ho\u1eb7c không có d\u1eef li\u1ec7u.
2025-01-29 12:34:18 - WARNING - Danh sách r\u1ed7ng ho\u1eb7c không có d\u1eef li\u1ec7u.
2025-01-29 12:34:21 - WARNING - Danh sách r\u1ed7ng ho\u1eb7c không có d\u1eef li\u1ec7u.
2025-01-29 12:34:24 - WARNING - Danh sách r\u1ed7ng ho\u1eb7c không có d\u1eef li\u1ec7u.
2025-01-29 12:34:27 - WARNING - Danh sách r\u1ed7ng ho\u1eb7c không có d\u1eef li\u1ec7u.
2025-01-29 12:34:30 - WARNING - Danh sách r\u1ed7ng ho\u1eb7c không có d\u1eef li\u1ec7u.
2025-01-29 12:34:33 - WARNING - Danh sách r\u1ed7ng ho\u1eb7c không có d\u1eef li\u1ec7u.
2025-01-29 12:34:36 - WARNING - Danh sách r\u1ed7ng ho\u1eb7c không có d\u1eef li\u1ec7u.
2025-01-29 12:34:39 - WARNING - Danh sách r\u1ed7ng ho\u1eb7c không có d\u1eef li\u1ec7u.
2025-01-29 12:34:42 - WARNING - Danh sách r\u1ed7ng ho\u1eb7c không có d\u1eef li\u1ec7u.
2025-01-29 12:34:45 - WARNING - Danh sách r\u1ed7ng ho\u1eb7c không có d\u1eef li\u1ec7u.
2025-01-29 12:34:48 - WARNING - Danh sách r\u1ed7ng ho\u1eb7c không có d\u1eef li\u1ec7u.
2025-01-29 12:34:51 - WARNING - Danh sách r\u1ed7ng ho\u1eb7c không có d\u1eef li\u1ec7u.
2025-01-29 12:34:54 - WARNING - Danh sách r\u1ed7ng ho\u1eb7c không có d\u1eef li\u1ec7u.
2025-01-29 12:34:57 - WARNING - Danh sách r\u1ed7ng ho\u1eb7c không có d\u1eef li\u1ec7u.
2025-01-29 12:35:12 - WARNING - PyNaCl is not installed, voice will NOT be supported
2025-01-29 12:35:12 - INFO - logging in using static token
2025-01-29 12:35:14 - INFO - Shard ID None has connected to Gateway (Session ID: ac132675588ef044700aab259b2fe97e).
2025-01-29 12:35:17 - WARNING - Danh sách r\u1ed7ng ho\u1eb7c không có d\u1eef li\u1ec7u.
2025-01-29 12:35:20 - WARNING - Danh sách r\u1ed7ng ho\u1eb7c không có d\u1eef li\u1ec7u.
2025-01-29 12:35:23 - WARNING - Danh sách r\u1ed7ng ho\u1eb7c không có d\u1eef li\u1ec7u.
2025-01-29 12:35:26 - WARNING - Danh sách r\u1ed7ng ho\u1eb7c không có d\u1eef li\u1ec7u.
2025-01-29 12:35:29 - WARNING - Danh sách r\u1ed7ng ho\u1eb7c không có d\u1eef li\u1ec7u.
2025-01-29 12:35:32 - WARNING - Danh sách r\u1ed7ng ho\u1eb7c không có d\u1eef li\u1ec7u.
2025-01-29 12:35:35 - WARNING - Danh sách r\u1ed7ng ho\u1eb7c không có d\u1eef li\u1ec7u.
2025-01-29 12:35:37 - WARNING - Không có thông tin \u0111\u0103ng nh\u1eadp
2025-01-29 12:35:38 - WARNING - Danh sách r\u1ed7ng ho\u1eb7c không có d\u1eef li\u1ec7u.
2025-01-29 12:35:41 - WARNING - Không có thông tin \u0111\u0103ng nh\u1eadp
2025-01-29 12:35:41 - WARNING - Danh sách r\u1ed7ng ho\u1eb7c không có d\u1eef li\u1ec7u.
2025-01-29 12:35:44 - WARNING - Danh sách r\u1ed7ng ho\u1eb7c không có d\u1eef li\u1ec7u.
2025-01-29 12:35:47 - WARNING - Danh sách r\u1ed7ng ho\u1eb7c không có d\u1eef li\u1ec7u.
2025-01-29 12:35:50 - WARNING - Danh sách r\u1ed7ng ho\u1eb7c không có d\u1eef li\u1ec7u.
2025-01-29 12:35:53 - WARNING - Danh sách r\u1ed7ng ho\u1eb7c không có d\u1eef li\u1ec7u.
2025-01-29 12:35:56 - WARNING - Danh sách r\u1ed7ng ho\u1eb7c không có d\u1eef li\u1ec7u.
2025-01-29 12:35:59 - WARNING - Danh sách r\u1ed7ng ho\u1eb7c không có d\u1eef li\u1ec7u.
2025-01-29 12:36:02 - WARNING - Danh sách r\u1ed7ng ho\u1eb7c không có d\u1eef li\u1ec7u.
2025-01-29 12:36:05 - WARNING - Danh sách r\u1ed7ng ho\u1eb7c không có d\u1eef li\u1ec7u.
2025-01-29 12:36:08 - WARNING - Danh sách r\u1ed7ng ho\u1eb7c không có d\u1eef li\u1ec7u.
2025-01-29 12:36:11 - WARNING - Danh sách r\u1ed7ng ho\u1eb7c không có d\u1eef li\u1ec7u.
2025-01-29 12:36:15 - WARNING - Danh sách r\u1ed7ng ho\u1eb7c không có d\u1eef li\u1ec7u.
2025-01-29 12:36:18 - WARNING - Danh sách r\u1ed7ng ho\u1eb7c không có d\u1eef li\u1ec7u.
2025-01-29 12:36:21 - WARNING - Danh sách r\u1ed7ng ho\u1eb7c không có d\u1eef li\u1ec7u.
2025-01-29 12:36:24 - WARNING - Danh sách r\u1ed7ng ho\u1eb7c không có d\u1eef li\u1ec7u.
2025-01-29 12:36:27 - WARNING - Danh sách r\u1ed7ng ho\u1eb7c không có d\u1eef li\u1ec7u.
2025-01-29 12:36:30 - WARNING - Danh sách r\u1ed7ng ho\u1eb7c không có d\u1eef li\u1ec7u.
2025-01-29 12:36:33 - WARNING - Danh sách r\u1ed7ng ho\u1eb7c không có d\u1eef li\u1ec7u.
2025-01-29 12:36:36 - WARNING - Danh sách r\u1ed7ng ho\u1eb7c không có d\u1eef li\u1ec7u.
2025-01-29 12:36:39 - WARNING - Danh sách r\u1ed7ng ho\u1eb7c không có d\u1eef li\u1ec7u.
2025-01-29 12:36:42 - WARNING - Danh sách r\u1ed7ng ho\u1eb7c không có d\u1eef li\u1ec7u.
2025-01-29 12:36:45 - WARNING - Danh sách r\u1ed7ng ho\u1eb7c không có d\u1eef li\u1ec7u.
2025-01-29 12:36:48 - WARNING - Danh sách r\u1ed7ng ho\u1eb7c không có d\u1eef li\u1ec7u.
2025-01-29 12:36:51 - WARNING - Danh sách r\u1ed7ng ho\u1eb7c không có d\u1eef li\u1ec7u.
2025-01-29 12:36:54 - WARNING - Danh sách r\u1ed7ng ho\u1eb7c không có d\u1eef li\u1ec7u.
2025-01-29 12:36:57 - WARNING - Danh sách r\u1ed7ng ho\u1eb7c không có d\u1eef li\u1ec7u.
2025-01-29 12:37:00 - WARNING - Danh sách r\u1ed7ng ho\u1eb7c không có d\u1eef li\u1ec7u.
2025-01-29 12:37:03 - WARNING - Danh sách r\u1ed7ng ho\u1eb7c không có d\u1eef li\u1ec7u.
2025-01-29 12:37:06 - WARNING - Danh sách r\u1ed7ng ho\u1eb7c không có d\u1eef li\u1ec7u.
2025-01-29 12:37:09 - WARNING - Danh sách r\u1ed7ng ho\u1eb7c không có d\u1eef li\u1ec7u.
2025-01-29 12:37:12 - WARNING - Danh sách r\u1ed7ng ho\u1eb7c không có d\u1eef li\u1ec7u.
2025-01-29 12:37:15 - WARNING - Danh sách r\u1ed7ng ho\u1eb7c không có d\u1eef li\u1ec7u.
2025-01-29 12:37:40 - WARNING - PyNaCl is not installed, voice will NOT be supported
2025-01-29 12:37:40 - INFO - logging in using static token
2025-01-29 12:37:42 - INFO - Shard ID None has connected to Gateway (Session ID: 4ee302bdeefaa5e5d525125a615b73fa).
2025-01-29 12:37:45 - WARNING - Danh sách r\u1ed7ng ho\u1eb7c không có d\u1eef li\u1ec7u.
2025-01-29 12:37:48 - WARNING - Danh sách r\u1ed7ng ho\u1eb7c không có d\u1eef li\u1ec7u.
2025-01-29 12:37:51 - WARNING - Danh sách r\u1ed7ng ho\u1eb7c không có d\u1eef li\u1ec7u.
2025-01-29 12:37:55 - WARNING - Danh sách r\u1ed7ng ho\u1eb7c không có d\u1eef li\u1ec7u.
2025-01-29 12:37:58 - WARNING - Danh sách r\u1ed7ng ho\u1eb7c không có d\u1eef li\u1ec7u.
2025-01-29 12:38:01 - WARNING - Danh sách r\u1ed7ng ho\u1eb7c không có d\u1eef li\u1ec7u.
2025-01-29 12:41:14 - WARNING - PyNaCl is not installed, voice will NOT be supported
2025-01-29 12:41:14 - INFO - logging in using static token
2025-01-29 12:41:15 - INFO - Shard ID None has connected to Gateway (Session ID: 8cb419bc0ae686a423e1f14b83776c9a).
2025-01-29 12:41:19 - WARNING - Danh sách r\u1ed7ng ho\u1eb7c không có d\u1eef li\u1ec7u.
2025-01-29 12:41:22 - WARNING - Danh sách r\u1ed7ng ho\u1eb7c không có d\u1eef li\u1ec7u.
2025-01-29 12:41:25 - WARNING - Danh sách r\u1ed7ng ho\u1eb7c không có d\u1eef li\u1ec7u.
2025-01-29 12:41:28 - WARNING - Danh sách r\u1ed7ng ho\u1eb7c không có d\u1eef li\u1ec7u.
2025-01-29 12:41:31 - WARNING - Danh sách r\u1ed7ng ho\u1eb7c không có d\u1eef li\u1ec7u.
2025-01-29 12:41:34 - WARNING - Danh sách r\u1ed7ng ho\u1eb7c không có d\u1eef li\u1ec7u.
2025-01-29 12:41:37 - WARNING - Danh sách r\u1ed7ng ho\u1eb7c không có d\u1eef li\u1ec7u.
2025-01-29 12:41:37 - ERROR - Ignoring exception in command 'login'
Traceback (most recent call last):
  File "C:\Users\huyth\AppData\Local\Programs\Python\Python313\Lib\site-packages\discord\app_commands\commands.py", line 858, in _do_call
    return await self._callback(interaction, **params)  # type: ignore
           ^^^^^^^^^^^^^^^^^^^^^^^^^^^^^^^^^^^^^^^^^^^
  File "c:\Users\huyth\OneDrive\Documents\Code\My projects\husci\public\app.py", line 40, in login
    await commands.handle_login(ctx, username, password)
  File "c:\Users\huyth\OneDrive\Documents\Code\My projects\husci\public\modules\commands.py", line 20, in handle_login
    await ctx.response.defer(ephemeral=True)
  File "C:\Users\huyth\AppData\Local\Programs\Python\Python313\Lib\site-packages\discord\interactions.py", line 709, in defer
    await adapter.create_interaction_response(
    ...<6 lines>...
    )
  File "C:\Users\huyth\AppData\Local\Programs\Python\Python313\Lib\site-packages\discord\webhook\async_.py", line 223, in request
    raise HTTPException(response, data)
discord.errors.HTTPException: 400 Bad Request (error code: 40060): Interaction has already been acknowledged.

The above exception was the direct cause of the following exception:

Traceback (most recent call last):
  File "C:\Users\huyth\AppData\Local\Programs\Python\Python313\Lib\site-packages\discord\app_commands\tree.py", line 1310, in _call
    await command._invoke_with_namespace(interaction, namespace)
  File "C:\Users\huyth\AppData\Local\Programs\Python\Python313\Lib\site-packages\discord\app_commands\commands.py", line 883, in _invoke_with_namespace
    return await self._do_call(interaction, transformed_values)
           ^^^^^^^^^^^^^^^^^^^^^^^^^^^^^^^^^^^^^^^^^^^^^^^^^^^^
  File "C:\Users\huyth\AppData\Local\Programs\Python\Python313\Lib\site-packages\discord\app_commands\commands.py", line 876, in _do_call
    raise CommandInvokeError(self, e) from e
discord.app_commands.errors.CommandInvokeError: Command 'login' raised an exception: HTTPException: 400 Bad Request (error code: 40060): Interaction has already been acknowledged.
2025-01-29 12:41:40 - WARNING - Danh sách r\u1ed7ng ho\u1eb7c không có d\u1eef li\u1ec7u.
2025-01-29 12:41:43 - WARNING - Danh sách r\u1ed7ng ho\u1eb7c không có d\u1eef li\u1ec7u.
2025-01-29 12:41:46 - WARNING - Danh sách r\u1ed7ng ho\u1eb7c không có d\u1eef li\u1ec7u.
2025-01-29 12:41:49 - WARNING - Danh sách r\u1ed7ng ho\u1eb7c không có d\u1eef li\u1ec7u.
2025-01-29 12:41:52 - WARNING - Danh sách r\u1ed7ng ho\u1eb7c không có d\u1eef li\u1ec7u.
2025-01-29 12:41:55 - WARNING - Danh sách r\u1ed7ng ho\u1eb7c không có d\u1eef li\u1ec7u.
2025-01-29 12:41:58 - WARNING - Danh sách r\u1ed7ng ho\u1eb7c không có d\u1eef li\u1ec7u.
2025-01-29 12:42:01 - WARNING - Danh sách r\u1ed7ng ho\u1eb7c không có d\u1eef li\u1ec7u.
2025-01-29 12:42:04 - WARNING - Danh sách r\u1ed7ng ho\u1eb7c không có d\u1eef li\u1ec7u.
2025-01-29 12:42:07 - WARNING - Danh sách r\u1ed7ng ho\u1eb7c không có d\u1eef li\u1ec7u.
2025-01-29 12:42:10 - WARNING - Danh sách r\u1ed7ng ho\u1eb7c không có d\u1eef li\u1ec7u.
2025-01-29 12:42:13 - WARNING - Danh sách r\u1ed7ng ho\u1eb7c không có d\u1eef li\u1ec7u.
2025-01-29 15:25:18 - WARNING - PyNaCl is not installed, voice will NOT be supported
2025-01-29 15:25:18 - INFO - logging in using static token
2025-01-29 15:25:20 - INFO - Shard ID None has connected to Gateway (Session ID: 86292f9212c0f9274f74ef4bd917192c).
2025-01-29 16:28:54 - ERROR - Ignoring exception in command 'first'
Traceback (most recent call last):
  File "C:\Users\huyth\AppData\Local\Programs\Python\Python313\Lib\site-packages\discord\app_commands\commands.py", line 858, in _do_call
    return await self._callback(interaction, **params)  # type: ignore
           ^^^^^^^^^^^^^^^^^^^^^^^^^^^^^^^^^^^^^^^^^^^
  File "c:\Users\huyth\OneDrive\Documents\Code\My projects\husci\public\app.py", line 49, in first
    await commands.handle_first(ctx)
  File "c:\Users\huyth\OneDrive\Documents\Code\My projects\husci\public\modules\commands.py", line 101, in handle_first
    await ctx.response.defer(ephemeral=False)
  File "C:\Users\huyth\AppData\Local\Programs\Python\Python313\Lib\site-packages\discord\interactions.py", line 709, in defer
    await adapter.create_interaction_response(
    ...<6 lines>...
    )
  File "C:\Users\huyth\AppData\Local\Programs\Python\Python313\Lib\site-packages\discord\webhook\async_.py", line 223, in request
    raise HTTPException(response, data)
discord.errors.HTTPException: 400 Bad Request (error code: 40060): Interaction has already been acknowledged.

The above exception was the direct cause of the following exception:

Traceback (most recent call last):
  File "C:\Users\huyth\AppData\Local\Programs\Python\Python313\Lib\site-packages\discord\app_commands\tree.py", line 1310, in _call
    await command._invoke_with_namespace(interaction, namespace)
  File "C:\Users\huyth\AppData\Local\Programs\Python\Python313\Lib\site-packages\discord\app_commands\commands.py", line 883, in _invoke_with_namespace
    return await self._do_call(interaction, transformed_values)
           ^^^^^^^^^^^^^^^^^^^^^^^^^^^^^^^^^^^^^^^^^^^^^^^^^^^^
  File "C:\Users\huyth\AppData\Local\Programs\Python\Python313\Lib\site-packages\discord\app_commands\commands.py", line 876, in _do_call
    raise CommandInvokeError(self, e) from e
discord.app_commands.errors.CommandInvokeError: Command 'first' raised an exception: HTTPException: 400 Bad Request (error code: 40060): Interaction has already been acknowledged.
2025-01-29 16:29:00 - ERROR - Ignoring exception in command 'notifications'
Traceback (most recent call last):
  File "C:\Users\huyth\AppData\Local\Programs\Python\Python313\Lib\site-packages\discord\app_commands\commands.py", line 858, in _do_call
    return await self._callback(interaction, **params)  # type: ignore
           ^^^^^^^^^^^^^^^^^^^^^^^^^^^^^^^^^^^^^^^^^^^
  File "c:\Users\huyth\OneDrive\Documents\Code\My projects\husci\public\app.py", line 46, in notifications
    await commands.handle_notifications(ctx)
  File "c:\Users\huyth\OneDrive\Documents\Code\My projects\husci\public\modules\commands.py", line 76, in handle_notifications
    await ctx.response.defer(ephemeral=False)
  File "C:\Users\huyth\AppData\Local\Programs\Python\Python313\Lib\site-packages\discord\interactions.py", line 709, in defer
    await adapter.create_interaction_response(
    ...<6 lines>...
    )
  File "C:\Users\huyth\AppData\Local\Programs\Python\Python313\Lib\site-packages\discord\webhook\async_.py", line 223, in request
    raise HTTPException(response, data)
discord.errors.HTTPException: 400 Bad Request (error code: 40060): Interaction has already been acknowledged.

The above exception was the direct cause of the following exception:

Traceback (most recent call last):
  File "C:\Users\huyth\AppData\Local\Programs\Python\Python313\Lib\site-packages\discord\app_commands\tree.py", line 1310, in _call
    await command._invoke_with_namespace(interaction, namespace)
  File "C:\Users\huyth\AppData\Local\Programs\Python\Python313\Lib\site-packages\discord\app_commands\commands.py", line 883, in _invoke_with_namespace
    return await self._do_call(interaction, transformed_values)
           ^^^^^^^^^^^^^^^^^^^^^^^^^^^^^^^^^^^^^^^^^^^^^^^^^^^^
  File "C:\Users\huyth\AppData\Local\Programs\Python\Python313\Lib\site-packages\discord\app_commands\commands.py", line 876, in _do_call
    raise CommandInvokeError(self, e) from e
discord.app_commands.errors.CommandInvokeError: Command 'notifications' raised an exception: HTTPException: 400 Bad Request (error code: 40060): Interaction has already been acknowledged.
2025-01-29 16:29:11 - ERROR - Ignoring exception in command 'lastscore'
Traceback (most recent call last):
  File "C:\Users\huyth\AppData\Local\Programs\Python\Python313\Lib\site-packages\discord\app_commands\commands.py", line 858, in _do_call
    return await self._callback(interaction, **params)  # type: ignore
           ^^^^^^^^^^^^^^^^^^^^^^^^^^^^^^^^^^^^^^^^^^^
  File "c:\Users\huyth\OneDrive\Documents\Code\My projects\husci\public\app.py", line 59, in last_score
    await commands.handle_last_score(ctx, bot)
  File "c:\Users\huyth\OneDrive\Documents\Code\My projects\husci\public\modules\commands.py", line 180, in handle_last_score
    await ctx.response.defer(ephemeral=True)
  File "C:\Users\huyth\AppData\Local\Programs\Python\Python313\Lib\site-packages\discord\interactions.py", line 709, in defer
    await adapter.create_interaction_response(
    ...<6 lines>...
    )
  File "C:\Users\huyth\AppData\Local\Programs\Python\Python313\Lib\site-packages\discord\webhook\async_.py", line 223, in request
    raise HTTPException(response, data)
discord.errors.HTTPException: 400 Bad Request (error code: 40060): Interaction has already been acknowledged.

The above exception was the direct cause of the following exception:

Traceback (most recent call last):
  File "C:\Users\huyth\AppData\Local\Programs\Python\Python313\Lib\site-packages\discord\app_commands\tree.py", line 1310, in _call
    await command._invoke_with_namespace(interaction, namespace)
  File "C:\Users\huyth\AppData\Local\Programs\Python\Python313\Lib\site-packages\discord\app_commands\commands.py", line 883, in _invoke_with_namespace
    return await self._do_call(interaction, transformed_values)
           ^^^^^^^^^^^^^^^^^^^^^^^^^^^^^^^^^^^^^^^^^^^^^^^^^^^^
  File "C:\Users\huyth\AppData\Local\Programs\Python\Python313\Lib\site-packages\discord\app_commands\commands.py", line 876, in _do_call
    raise CommandInvokeError(self, e) from e
discord.app_commands.errors.CommandInvokeError: Command 'lastscore' raised an exception: HTTPException: 400 Bad Request (error code: 40060): Interaction has already been acknowledged.
2025-01-29 16:29:22 - ERROR - Ignoring exception in command 'scoretable'
Traceback (most recent call last):
  File "C:\Users\huyth\AppData\Local\Programs\Python\Python313\Lib\site-packages\discord\app_commands\commands.py", line 858, in _do_call
    return await self._callback(interaction, **params)  # type: ignore
           ^^^^^^^^^^^^^^^^^^^^^^^^^^^^^^^^^^^^^^^^^^^
  File "c:\Users\huyth\OneDrive\Documents\Code\My projects\husci\public\app.py", line 62, in full_score
    await commands.handle_full_score(ctx, bot)
  File "c:\Users\huyth\OneDrive\Documents\Code\My projects\husci\public\modules\commands.py", line 219, in handle_full_score
    await ctx.response.defer(ephemeral=True)
  File "C:\Users\huyth\AppData\Local\Programs\Python\Python313\Lib\site-packages\discord\interactions.py", line 709, in defer
    await adapter.create_interaction_response(
    ...<6 lines>...
    )
  File "C:\Users\huyth\AppData\Local\Programs\Python\Python313\Lib\site-packages\discord\webhook\async_.py", line 223, in request
    raise HTTPException(response, data)
discord.errors.HTTPException: 400 Bad Request (error code: 40060): Interaction has already been acknowledged.

The above exception was the direct cause of the following exception:

Traceback (most recent call last):
  File "C:\Users\huyth\AppData\Local\Programs\Python\Python313\Lib\site-packages\discord\app_commands\tree.py", line 1310, in _call
    await command._invoke_with_namespace(interaction, namespace)
  File "C:\Users\huyth\AppData\Local\Programs\Python\Python313\Lib\site-packages\discord\app_commands\commands.py", line 883, in _invoke_with_namespace
    return await self._do_call(interaction, transformed_values)
           ^^^^^^^^^^^^^^^^^^^^^^^^^^^^^^^^^^^^^^^^^^^^^^^^^^^^
  File "C:\Users\huyth\AppData\Local\Programs\Python\Python313\Lib\site-packages\discord\app_commands\commands.py", line 876, in _do_call
    raise CommandInvokeError(self, e) from e
discord.app_commands.errors.CommandInvokeError: Command 'scoretable' raised an exception: HTTPException: 400 Bad Request (error code: 40060): Interaction has already been acknowledged.
2025-01-29 16:29:41 - ERROR - Ignoring exception in command 'message'
Traceback (most recent call last):
  File "C:\Users\huyth\AppData\Local\Programs\Python\Python313\Lib\site-packages\discord\app_commands\commands.py", line 858, in _do_call
    return await self._callback(interaction, **params)  # type: ignore
           ^^^^^^^^^^^^^^^^^^^^^^^^^^^^^^^^^^^^^^^^^^^
  File "c:\Users\huyth\OneDrive\Documents\Code\My projects\husci\public\app.py", line 56, in message
    await commands.handle_message(ctx)
  File "c:\Users\huyth\OneDrive\Documents\Code\My projects\husci\public\modules\commands.py", line 144, in handle_message
    await ctx.response.defer(ephemeral=True)
  File "C:\Users\huyth\AppData\Local\Programs\Python\Python313\Lib\site-packages\discord\interactions.py", line 709, in defer
    await adapter.create_interaction_response(
    ...<6 lines>...
    )
  File "C:\Users\huyth\AppData\Local\Programs\Python\Python313\Lib\site-packages\discord\webhook\async_.py", line 223, in request
    raise HTTPException(response, data)
discord.errors.HTTPException: 400 Bad Request (error code: 40060): Interaction has already been acknowledged.

The above exception was the direct cause of the following exception:

Traceback (most recent call last):
  File "C:\Users\huyth\AppData\Local\Programs\Python\Python313\Lib\site-packages\discord\app_commands\tree.py", line 1310, in _call
    await command._invoke_with_namespace(interaction, namespace)
  File "C:\Users\huyth\AppData\Local\Programs\Python\Python313\Lib\site-packages\discord\app_commands\commands.py", line 883, in _invoke_with_namespace
    return await self._do_call(interaction, transformed_values)
           ^^^^^^^^^^^^^^^^^^^^^^^^^^^^^^^^^^^^^^^^^^^^^^^^^^^^
  File "C:\Users\huyth\AppData\Local\Programs\Python\Python313\Lib\site-packages\discord\app_commands\commands.py", line 876, in _do_call
    raise CommandInvokeError(self, e) from e
discord.app_commands.errors.CommandInvokeError: Command 'message' raised an exception: HTTPException: 400 Bad Request (error code: 40060): Interaction has already been acknowledged.
2025-01-29 18:37:53 - INFO - Shard ID None has successfully RESUMED session 86292f9212c0f9274f74ef4bd917192c.
2025-01-29 18:39:29 - ERROR - Attempting a reconnect in 0.64s
Traceback (most recent call last):
  File "C:\Users\huyth\AppData\Local\Programs\Python\Python313\Lib\site-packages\discord\client.py", line 667, in connect
    await self.ws.poll_event()
  File "C:\Users\huyth\AppData\Local\Programs\Python\Python313\Lib\site-packages\discord\gateway.py", line 625, in poll_event
    await self.received_message(msg.data)
  File "C:\Users\huyth\AppData\Local\Programs\Python\Python313\Lib\site-packages\discord\gateway.py", line 533, in received_message
    await self.send_as_json(beat)
  File "C:\Users\huyth\AppData\Local\Programs\Python\Python313\Lib\site-packages\discord\gateway.py", line 661, in send_as_json
    await self.send(utils._to_json(data))
  File "C:\Users\huyth\AppData\Local\Programs\Python\Python313\Lib\site-packages\discord\gateway.py", line 657, in send
    await self.socket.send_str(data)
  File "C:\Users\huyth\AppData\Local\Programs\Python\Python313\Lib\site-packages\aiohttp\client_ws.py", line 243, in send_str
    await self._writer.send_frame(
        data.encode("utf-8"), WSMsgType.TEXT, compress=compress
    )
  File "C:\Users\huyth\AppData\Local\Programs\Python\Python313\Lib\site-packages\aiohttp\_websocket\writer.py", line 125, in send_frame
    raise ClientConnectionResetError("Cannot write to closing transport")
aiohttp.client_exceptions.ClientConnectionResetError: Cannot write to closing transport
2025-01-29 18:39:30 - INFO - Shard ID None has successfully RESUMED session 86292f9212c0f9274f74ef4bd917192c.
2025-01-29 19:28:28 - INFO - Shard ID None has successfully RESUMED session 86292f9212c0f9274f74ef4bd917192c.
2025-01-29 20:45:34 - ERROR - Ignoring exception in command 'scoretable'
Traceback (most recent call last):
  File "C:\Users\huyth\AppData\Local\Programs\Python\Python313\Lib\site-packages\discord\app_commands\commands.py", line 858, in _do_call
    return await self._callback(interaction, **params)  # type: ignore
           ^^^^^^^^^^^^^^^^^^^^^^^^^^^^^^^^^^^^^^^^^^^
  File "c:\Users\huyth\OneDrive\Documents\Code\My projects\husci\public\app.py", line 62, in full_score
    await commands.handle_full_score(ctx, bot)
  File "c:\Users\huyth\OneDrive\Documents\Code\My projects\husci\public\modules\commands.py", line 219, in handle_full_score
    await ctx.response.defer(ephemeral=True)
  File "C:\Users\huyth\AppData\Local\Programs\Python\Python313\Lib\site-packages\discord\interactions.py", line 709, in defer
    await adapter.create_interaction_response(
    ...<6 lines>...
    )
  File "C:\Users\huyth\AppData\Local\Programs\Python\Python313\Lib\site-packages\discord\webhook\async_.py", line 223, in request
    raise HTTPException(response, data)
discord.errors.HTTPException: 400 Bad Request (error code: 40060): Interaction has already been acknowledged.

The above exception was the direct cause of the following exception:

Traceback (most recent call last):
  File "C:\Users\huyth\AppData\Local\Programs\Python\Python313\Lib\site-packages\discord\app_commands\tree.py", line 1310, in _call
    await command._invoke_with_namespace(interaction, namespace)
  File "C:\Users\huyth\AppData\Local\Programs\Python\Python313\Lib\site-packages\discord\app_commands\commands.py", line 883, in _invoke_with_namespace
    return await self._do_call(interaction, transformed_values)
           ^^^^^^^^^^^^^^^^^^^^^^^^^^^^^^^^^^^^^^^^^^^^^^^^^^^^
  File "C:\Users\huyth\AppData\Local\Programs\Python\Python313\Lib\site-packages\discord\app_commands\commands.py", line 876, in _do_call
    raise CommandInvokeError(self, e) from e
discord.app_commands.errors.CommandInvokeError: Command 'scoretable' raised an exception: HTTPException: 400 Bad Request (error code: 40060): Interaction has already been acknowledged.
2025-01-29 21:53:51 - INFO - Shard ID None has successfully RESUMED session 86292f9212c0f9274f74ef4bd917192c.
2025-01-30 02:29:33 - ERROR - Attempting a reconnect in 1.91s
Traceback (most recent call last):
  File "C:\Users\huyth\AppData\Local\Programs\Python\Python313\Lib\site-packages\aiohttp\connector.py", line 1345, in _create_direct_connection
    hosts = await self._resolve_host(host, port, traces=traces)
            ^^^^^^^^^^^^^^^^^^^^^^^^^^^^^^^^^^^^^^^^^^^^^^^^^^^
  File "C:\Users\huyth\AppData\Local\Programs\Python\Python313\Lib\site-packages\aiohttp\connector.py", line 989, in _resolve_host
    return await asyncio.shield(resolved_host_task)
           ^^^^^^^^^^^^^^^^^^^^^^^^^^^^^^^^^^^^^^^^
  File "C:\Users\huyth\AppData\Local\Programs\Python\Python313\Lib\site-packages\aiohttp\connector.py", line 1020, in _resolve_host_with_throttle
    addrs = await self._resolver.resolve(host, port, family=self._family)
            ^^^^^^^^^^^^^^^^^^^^^^^^^^^^^^^^^^^^^^^^^^^^^^^^^^^^^^^^^^^^^
  File "C:\Users\huyth\AppData\Local\Programs\Python\Python313\Lib\site-packages\aiohttp\resolver.py", line 36, in resolve
    infos = await self._loop.getaddrinfo(
            ^^^^^^^^^^^^^^^^^^^^^^^^^^^^^
    ...<5 lines>...
    )
    ^
  File "C:\Users\huyth\AppData\Local\Programs\Python\Python313\Lib\asyncio\base_events.py", line 934, in getaddrinfo
    return await self.run_in_executor(
           ^^^^^^^^^^^^^^^^^^^^^^^^^^^
        None, getaddr_func, host, port, family, type, proto, flags)
        ^^^^^^^^^^^^^^^^^^^^^^^^^^^^^^^^^^^^^^^^^^^^^^^^^^^^^^^^^^^
  File "C:\Users\huyth\AppData\Local\Programs\Python\Python313\Lib\concurrent\futures\thread.py", line 59, in run
    result = self.fn(*self.args, **self.kwargs)
  File "C:\Users\huyth\AppData\Local\Programs\Python\Python313\Lib\socket.py", line 975, in getaddrinfo
    for res in _socket.getaddrinfo(host, port, family, type, proto, flags):
               ~~~~~~~~~~~~~~~~~~~^^^^^^^^^^^^^^^^^^^^^^^^^^^^^^^^^^^^^^^^
socket.gaierror: [Errno 11001] getaddrinfo failed

The above exception was the direct cause of the following exception:

Traceback (most recent call last):
  File "C:\Users\huyth\AppData\Local\Programs\Python\Python313\Lib\site-packages\discord\client.py", line 664, in connect
    self.ws = await asyncio.wait_for(coro, timeout=60.0)
              ^^^^^^^^^^^^^^^^^^^^^^^^^^^^^^^^^^^^^^^^^^
  File "C:\Users\huyth\AppData\Local\Programs\Python\Python313\Lib\asyncio\tasks.py", line 507, in wait_for
    return await fut
           ^^^^^^^^^
  File "C:\Users\huyth\AppData\Local\Programs\Python\Python313\Lib\site-packages\discord\gateway.py", line 374, in from_client
    socket = await client.http.ws_connect(str(url))
             ^^^^^^^^^^^^^^^^^^^^^^^^^^^^^^^^^^^^^^
  File "C:\Users\huyth\AppData\Local\Programs\Python\Python313\Lib\site-packages\discord\http.py", line 550, in ws_connect
    return await self.__session.ws_connect(url, **kwargs)
           ^^^^^^^^^^^^^^^^^^^^^^^^^^^^^^^^^^^^^^^^^^^^^^
  File "C:\Users\huyth\AppData\Local\Programs\Python\Python313\Lib\site-packages\aiohttp\client.py", line 1002, in _ws_connect
    resp = await self.request(
           ^^^^^^^^^^^^^^^^^^^
    ...<11 lines>...
    )
    ^
  File "C:\Users\huyth\AppData\Local\Programs\Python\Python313\Lib\site-packages\aiohttp\client.py", line 701, in _request
    conn = await self._connector.connect(
           ^^^^^^^^^^^^^^^^^^^^^^^^^^^^^^
        req, traces=traces, timeout=real_timeout
        ^^^^^^^^^^^^^^^^^^^^^^^^^^^^^^^^^^^^^^^^
    )
    ^
  File "C:\Users\huyth\AppData\Local\Programs\Python\Python313\Lib\site-packages\aiohttp\connector.py", line 544, in connect
    proto = await self._create_connection(req, traces, timeout)
            ^^^^^^^^^^^^^^^^^^^^^^^^^^^^^^^^^^^^^^^^^^^^^^^^^^^
  File "C:\Users\huyth\AppData\Local\Programs\Python\Python313\Lib\site-packages\aiohttp\connector.py", line 1050, in _create_connection
    _, proto = await self._create_direct_connection(req, traces, timeout)
               ^^^^^^^^^^^^^^^^^^^^^^^^^^^^^^^^^^^^^^^^^^^^^^^^^^^^^^^^^^
  File "C:\Users\huyth\AppData\Local\Programs\Python\Python313\Lib\site-packages\aiohttp\connector.py", line 1351, in _create_direct_connection
    raise ClientConnectorDNSError(req.connection_key, exc) from exc
aiohttp.client_exceptions.ClientConnectorDNSError: Cannot connect to host gateway-us-east1-b.discord.gg:443 ssl:default [getaddrinfo failed]
2025-01-30 02:29:37 - INFO - Shard ID None session has been invalidated.
2025-01-30 02:29:43 - INFO - Shard ID None has connected to Gateway (Session ID: 7b9f3a1dbebcc4a42db0e4ef79b84659).
2025-01-30 02:29:48 - ERROR - Ignoring exception in on_ready
Traceback (most recent call last):
  File "C:\Users\huyth\AppData\Local\Programs\Python\Python313\Lib\site-packages\discord\client.py", line 449, in _run_event
    await coro(*args, **kwargs)
  File "c:\Users\huyth\OneDrive\Documents\Code\My projects\husci\public\app.py", line 81, in on_ready
    one_second.start()
    ~~~~~~~~~~~~~~~~^^
  File "C:\Users\huyth\AppData\Local\Programs\Python\Python313\Lib\site-packages\discord\ext\tasks\__init__.py", line 395, in start
    raise RuntimeError('Task is already launched and is not completed.')
RuntimeError: Task is already launched and is not completed.
2025-02-03 11:01:20 - WARNING - PyNaCl is not installed, voice will NOT be supported
2025-02-03 11:01:20 - INFO - logging in using static token
2025-02-03 11:54:05 - WARNING - PyNaCl is not installed, voice will NOT be supported
2025-02-03 11:54:05 - INFO - logging in using static token
2025-02-03 11:54:06 - INFO - Shard ID None has connected to Gateway (Session ID: 22527f48110966b216b185651c6dbc53).
